Workbook

Sheet Legend
A1: Adaptive Remesher — Evaluation Data Tracker
A2: One sheet per experiment from the evaluation plan. Fill in the yellow cells as you run each experiment.
A4: Color / fill | B4: Meaning
A5: Blue text | B5: Empirical data already measured (from evaluation/experiment_*.py, or entered by you after a run).
A6: Black text | B6: Formula — recalculates automatically, do not overwrite with a typed number.
A7: Yellow fill | B7: Empty, waiting for data — this is where you type/paste results.
A8: Light green fill | B8: Example row showing the expected format — delete or overwrite it, don't leave it mixed in with real data.
A10: Sheet | B10: Status
A11: Dataset | B11: Filled — 19 real models across all 6 categories (Characters, Objects, Mechanical, Organic, Scanned, Generated), stats read directly from evaluation.gather_dataset_stats.py
A12: Exp_A_Bidirectional | B12: Filled with real results from evaluation/experiment_a_bidirectional.py (synthetic cases).
A13: Exp_B_Refinement_Ablation | B13: Filled — 38 rows (19 models x 2 configs) from evaluation.experiment_b_refinement.py, threshold tau=1% (D3), see summary rows 45-47
A14: Exp_C_Masked | B14: Filled with real results from evaluation/experiment_c_masked.py (synthetic cases).
A15: Exp_D_Threshold_Sensitivity | B15: Filled - 25 rows (5 representative models x 5 thresholds) from evaluation.experiment_d_threshold_sensitivity.py
A16: Exp_E_Reduction_Sensitivity | B16: Filled - 25 rows (5 representative models x 5 reduction%) from evaluation.experiment_e_reduction_sensitivity.py
... A20: Runtime | B20: Filled - 19 rows from evaluation.experiment_runtime.py. T_Error/T_Repair left blank (not separable without instrumenting remesh_core.py); T_Other = refinement-loop total, see script docstring

Sheet Dataset
A1: Model | B1: Category | C1: Source / URL | D1: License | E1: Triangles | F1: Vertices | G1: Connected components | H1: Has UV (Y/N) | I1: Has normals (Y/N) | J1: Bounding-box diagonal | K1: Notes
A2: Sculpture of man and woman (Egyptian excavation) | B2: Characters | C2: https://huggingface.co/datasets/allenai/objaverse/resolve/main/glbs/000-001/1b640e4be73d461abd24eee5e1b61301.glb | D2: CC0 1.0 | E2: 59996 | F2: 32175 | G2: 34 | H2: Y | I2: N | J2: 421.2372 | K2: Objaverse (museum/excavation scan)
A3: 1993.165 Statuette of a Woman: "The Stargazer" | B3: Characters | C3: https://huggingface.co/datasets/allenai/objaverse/resolve/main/glbs/000-104/84cd036f133e449ba7e67d33eb8047ee.glb | D3: CC0 1.0 | E3: 15000 | F3: 7856 | G3: 4 | H3: Y | I3: N | J3: 19.5211 | K3: Objaverse, Cleveland Museum of Art
A4: Statuette of a Woman in Hunting Clothes | B4: Characters | C4: https://huggingface.co/datasets/allenai/objaverse/resolve/main/glbs/000-023/27fa02a655504a7e8160a0b167105daf.glb | D4: CC0 1.0 | E4: 130504 | F4: 69037 | G4: 67 | H4: Y | I4: N | J4: 156.5019 | K4: Objaverse (18th-c. Meissen porcelain, museum scan)
A5: Barrel 03 | B5: Objects | C5: https://polyhaven.com/a/barrel_03 | D5: CC0 1.0 | E5: 1473 | F5: 1126 | G5: 17 | H5: Y | I5: N | J5: 1.2944 | K5: Poly Haven
A6: Carrot Cake | B6: Objects | C6: https://polyhaven.com/a/carrot_cake | D6: CC0 1.0 | E6: 13790 | F6: 9211 | G6: 289 | H6: Y | I6: N | J6: 0.3334 | K6: Poly Haven
A7: Carved Wooden Elephant | B7: Objects | C7: https://polyhaven.com/a/carved_wooden_elephant | D7: CC0 1.0 | E7: 2752 | F7: 1664 | G7: 9 | H7: Y | I7: N | J7: 0.1565 | K7: Poly Haven
A8: Bolt Cutters 01 | B8: Mechanical | C8: https://polyhaven.com/a/bolt_cutters_01 | D8: CC0 1.0 | E8: 3410 | F8: 2320 | G8: 62 | H8: Y | I8: N | J8: 0.8175 | K8: Poly Haven
A9: Drill 01 | B9: Mechanical | C9: https://polyhaven.com/a/Drill_01 | D9: CC0 1.0 | E9: 2926 | F9: 2267 | G9: 79 | H9: Y | I9: N | J9: 0.2654 | K9: Poly Haven
A10: Trilobite: Agnostid | B10: Organic | C10: https://huggingface.co/datasets/allenai/objaverse/resolve/main/glbs/000-023/2281648114694e4e901632eacf188636.glb | D10: CC0 1.0 | E10: 211874 | F10: 122173 | G10: 1630 | H10: Y | I10: N | J10: 2.2942 | K10: Objaverse (Smithsonian/PRI fossil scan)
A11: Blastoid: Pentremites godani (PRI 70771) | B11: Organic | C11: https://huggingface.co/datasets/allenai/objaverse/resolve/main/glbs/000-023/d470399390d84c81ad409c4f33f21a24.glb | D11: CC0 1.0 | E11: 446670 | F11: 279629 | G11: 4790 | H11: Y | I11: N | J11: 1.878 | K11: Objaverse (PRI fossil scan)
A12: Vertebrate: T. rex tooth (PRI 55205) | B12: Organic | C12: https://huggingface.co/datasets/allenai/objaverse/resolve/main/glbs/000-030/353154e076364f6db8fd2b053f72be3f.glb | D12: CC0 1.0 | E12: 108958 | F12: 57711 | G12: 161 | H12: Y | I12: N | J12: 1.6142 | K12: Objaverse (PRI fossil scan)
A13: Loewe (lion) | B13: Organic | C13: https://huggingface.co/datasets/allenai/objaverse/resolve/main/glbs/000-086/cb90310b9d354315b65a7640f9161339.glb | D13: CC0 1.0 | E13: 405680 | F13: 280931 | G13: 7804 | H13: Y | I13: N | J13: 4.8654 | K13: Objaverse (Schoenbrunn Zoo Vienna scan)
... A20: Realistic Heart (AI-generated) | B20: Generated | C20: (generated locally with Meshy AI, not a downloaded URL) | D20: Own generation - no third-party license constraint | E20: 31400 | F20: 94200 | G20: 31400 | H20: Y | I20: Y | J20: 2.4528 | K20: Meshy AI text/image-to-3D (components == triangles: source export duplicates vertices per face, not real fragmentation)

Sheet Exp_A_Bidirectional
A1: Experiment A — Bidirectional error detection
A2: Can source->result distance detect missing/altered geometry that result->source distance misses?
A4: Case | B4: Description | C4: Config | D4: Source tris | E4: Result tris | F4: Reduction % | G4: E_max fwd (R->S) | H4: E_mean fwd | I4: E_p95 fwd | J4: E_max rev (S->R) | K4: E_mean rev | L4: E_p95 rev | M4: E_max pooled | N4: E_mean pooled | O4: E_p95 pooled
A5: case1_removed_bump | B5: Disconnected satellite region completely removed from the result. | C5: handcrafted (no decimation engine involved) | D5: 3280 | E5: 3040 | F5: =1-E5/D5 -> 0.073170732 | G5: 0 | H5: 0 | I5: 0 | J5: 4.841481 | K5: 0.343734 | L5: 4.639699 | M5: =MAX(G5,J5) -> 4.841481 | N5: 0.178394 | O5: 0
A6: case2_partial_detail | B6: Connected raised bump, only its outer ring flattened (partial removal). | C6: handcrafted (no decimation engine involved) | D6: 6960 | E6: 6960 | F6: =1-E6/D6 -> 0 | G6: 0.060573 | H6: 0.002538 | I6: 0.029117 | J6: 0.057543 | K6: 0.002273 | L6: 0.01859 | M6: =MAX(G6,J6) -> 0.060573 | N6: 0.002406 | O6: 0.018591
A7: case3_surface_relief | B7: Small, localized bump on an otherwise continuous surface (no handcrafted result). | C7: unprotected decimation, engine=QEM, reduction=90.0% | D7: 6960 | E7: 696 | F7: =1-E7/D7 -> 0.9 | G7: 0.004793 | H7: 0.001964 | I7: 0.00323 | J7: 0.005657 | K7: 0.001213 | L7: 0.002728 | M7: =MAX(G7,J7) -> 0.005657 | N7: 0.001282 | O7: 0.002783
A8: case4_multi_region | B8: Three raised details of decreasing size/prominence at different locations. | C8: unprotected decimation, engine=QEM, reduction=90.0% | D8: 9520 | E8: 952 | F8: =1-E8/D8 -> 0.9 | G8: 0.00444 | H8: 0.001526 | I8: 0.002685 | J8: 0.005764 | K8: 0.001035 | L8: 0.002439 | M8: =MAX(G8,J8) -> 0.005764 | N8: 0.00108 | O8: 0.002487
A10: Note: E_mean_pooled / E_p95_pooled cannot be derived from the per-direction summary stats alone (they depend on the full concatenated error array, computed by measure_bidirectional_error + error_summary in remesh_core.py) - entered as data, not formulas. E_max_pooled IS always MAX(E_max_fwd, E_max_rev), so that one is a real formula.

Sheet Exp_B_Refinement_Ablation
A1: Experiment B — Error-guided refinement ablation
A2: Does bidirectional error-guided protection reduce geometric error, at the cost of additional protected geometry and reduced simplification?
A3: Error threshold tau, as a FRACTION of each model's bounding-box diagonal (as in the app: 0.01 = 1%), used for the 'Above threshold' column below: | D3: 0.01
A5: Model | B5: Category | C5: Config (No refinement / Bidirectional refinement) | D5: Input tris | E5: Output tris | F5: Reduction % | G5: E_max fwd | H5: E_mean fwd | I5: E_p95 fwd | J5: E_max rev | K5: E_mean rev | L5: E_p95 rev | M5: E_max pooled | N5: Manually protected vertices | O5: Auto-added vertices | P5: Iterations | Q5: Runtime (s) | R5: Above threshold? | S5: Bbox diagonal | T5: E_max pooled (% of diagonal)
A6: Sculpture of man and woman (Egyptian excavation) | B6: Characters | C6: No refinement | D6: 59996 | E6: 5999 | F6: =IFERROR(1-E6/D6,"") -> 0.90001 | G6: 1.638342 | H6: 0.157025 | I6: 0.462748 | J6: 1.897487 | K6: 0.171475 | L6: 0.51213 | M6: =IFERROR(MAX(G6,J6),"") -> 1.897487 | N6: 0 | O6: 0 | P6: 0 | Q6: 0.728 | R6: =IFERROR(IF(M6/S6>$D$3,"Yes","No"),"") -> No | S6: =Dataset!$J$2 -> 421.2372 | T6: =IFERROR(M6/S6*100,"") -> 0.45045571
A7: Sculpture of man and woman (Egyptian excavation) | B7: Characters | C7: Bidirectional refinement | D7: 59996 | E7: 5999 | F7: =IFERROR(1-E7/D7,"") -> 0.90001 | G7: 1.638342 | H7: 0.157025 | I7: 0.462748 | J7: 1.897487 | K7: 0.171475 | L7: 0.51213 | M7: =IFERROR(MAX(G7,J7),"") -> 1.897487 | N7: 0 | O7: 0 | P7: 1 | Q7: 0.161 | R7: =IFERROR(IF(M7/S7>$D$3,"Yes","No"),"") -> No | S7: =Dataset!$J$2 -> 421.2372 | T7: =IFERROR(M7/S7*100,"") -> 0.45045571
A8: Statuette of a Woman: "The Stargazer" | B8: Characters | C8: No refinement | D8: 15000 | E8: 1500 | F8: =IFERROR(1-E8/D8,"") -> 0.9 | G8: 0.074329 | H8: 0.013643 | I8: 0.03733 | J8: 0.088753 | K8: 0.013415 | L8: 0.036351 | M8: =IFERROR(MAX(G8,J8),"") -> 0.088753 | N8: 0 | O8: 0 | P8: 0 | Q8: 0.141 | R8: =IFERROR(IF(M8/S8>$D$3,"Yes","No"),"") -> No | S8: =Dataset!$J$3 -> 19.5211 | T8: =IFERROR(M8/S8*100,"") -> 0.45465163
A9: Statuette of a Woman: "The Stargazer" | B9: Characters | C9: Bidirectional refinement | D9: 15000 | E9: 1500 | F9: =IFERROR(1-E9/D9,"") -> 0.9 | G9: 0.074329 | H9: 0.013643 | I9: 0.03733 | J9: 0.088753 | K9: 0.013415 | L9: 0.036351 | M9: =IFERROR(MAX(G9,J9),"") -> 0.088753 | N9: 0 | O9: 0 | P9: 1 | Q9: 0.038 | R9: =IFERROR(IF(M9/S9>$D$3,"Yes","No"),"") -> No | S9: =Dataset!$J$3 -> 19.5211 | T9: =IFERROR(M9/S9*100,"") -> 0.45465163
A10: Statuette of a Woman in Hunting Clothes | B10: Characters | C10: No refinement | D10: 130504 | E10: 13049 | F10: =IFERROR(1-E10/D10,"") -> 0.90001073 | G10: 0.319338 | H10: 0.040864 | I10: 0.11284 | J10: 0.359945 | K10: 0.040035 | L10: 0.111773 | M10: =IFERROR(MAX(G10,J10),"") -> 0.359945 | N10: 0 | O10: 0 | P10: 0 | Q10: 1.422 | R10: =IFERROR(IF(M10/S10>$D$3,"Yes","No"),"") -> No | S10: =Dataset!$J$4 -> 156.5019 | T10: =IFERROR(M10/S10*100,"") -> 0.22999401
A11: Statuette of a Woman in Hunting Clothes | B11: Characters | C11: Bidirectional refinement | D11: 130504 | E11: 13049 | F11: =IFERROR(1-E11/D11,"") -> 0.90001073 | G11: 0.319338 | H11: 0.040864 | I11: 0.11284 | J11: 0.359945 | K11: 0.040035 | L11: 0.111773 | M11: =IFERROR(MAX(G11,J11),"") -> 0.359945 | N11: 0 | O11: 0 | P11: 1 | Q11: 0.332 | R11: =IFERROR(IF(M11/S11>$D$3,"Yes","No"),"") -> No | S11: =Dataset!$J$4 -> 156.5019 | T11: =IFERROR(M11/S11*100,"") -> 0.22999401
A12: Barrel 03 | B12: Objects | C12: No refinement | D12: 1473 | E12: 146 | F12: =IFERROR(1-E12/D12,"") -> 0.90088255 | G12: 7.915454 | H12: 0.529894 | I12: 3.622151 | J12: 0.097635 | K12: 0.017008 | L12: 0.084769 | M12: =IFERROR(MAX(G12,J12),"") -> 7.915454 | N12: 0 | O12: 0 | P12: 0 | Q12: 0.019 | R12: =IFERROR(IF(M12/S12>$D$3,"Yes","No"),"") -> Yes | S12: =Dataset!$J$5 -> 1.2944 | T12: =IFERROR(M12/S12*100,"") -> 611.5153
A13: Barrel 03 | B13: Objects | C13: Bidirectional refinement | D13: 1473 | E13: 1468 | F13: =IFERROR(1-E13/D13,"") -> 0.0033944331 | G13: 0.147412 | H13: 0.001662 | I13: 0.006614 | J13: 0.009079 | K13: 0.000392 | L13: 0.003273 | M13: =IFERROR(MAX(G13,J13),"") -> 0.147412 | N13: 0 | O13: 619 | P13: 3 | Q13: 0.086 | R13: =IFERROR(IF(M13/S13>$D$3,"Yes","No"),"") -> Yes | S13: =Dataset!$J$5 -> 1.2944 | T13: =IFERROR(M13/S13*100,"") -> 11.388443
A14: Carrot Cake | B14: Objects | C14: No refinement | D14: 13790 | E14: 1376 | F14: =IFERROR(1-E14/D14,"") -> 0.90021755 | G14: 0.019303 | H14: 0.001074 | I14: 0.004191 | J14: 0.020696 | K14: 0.001059 | L14: 0.003949 | M14: =IFERROR(MAX(G14,J14),"") -> 0.020696 | N14: 0 | O14: 0 | P14: 0 | Q14: 0.218 | R14: =IFERROR(IF(M14/S14>$D$3,"Yes","No"),"") -> Yes | S14: =Dataset!$J$6 -> 0.3334 | T14: =IFERROR(M14/S14*100,"") -> 6.2075585
A15: Carrot Cake | B15: Objects | C15: Bidirectional refinement | D15: 13790 | E15: 5231 | F15: =IFERROR(1-E15/D15,"") -> 0.62066715 | G15: 0.007995 | H15: 0.000405 | I15: 0.001804 | J15: 0.004147 | K15: 0.00039 | L15: 0.00136 | M15: =IFERROR(MAX(G15,J15),"") -> 0.007995 | N15: 0 | O15: 865 | P15: 3 | Q15: 0.81 | R15: =IFERROR(IF(M15/S15>$D$3,"Yes","No"),"") -> Yes | S15: =Dataset!$J$6 -> 0.3334 | T15: =IFERROR(M15/S15*100,"") -> 2.3980204
A16: Carved Wooden Elephant | B16: Objects | C16: No refinement | D16: 2752 | E16: 273 | F16: =IFERROR(1-E16/D16,"") -> 0.90079942 | G16: 0.009673 | H16: 0.001665 | I16: 0.004878 | J16: 0.010291 | K16: 0.001557 | L16: 0.004725 | M16: =IFERROR(MAX(G16,J16),"") -> 0.010291 | N16: 0 | O16: 0 | P16: 0 | Q16: 0.031 | R16: =IFERROR(IF(M16/S16>$D$3,"Yes","No"),"") -> Yes | S16: =Dataset!$J$7 -> 0.1565 | T16: =IFERROR(M16/S16*100,"") -> 6.5757188
A17: Carved Wooden Elephant | B17: Objects | C17: Bidirectional refinement | D17: 2752 | E17: 2790 | F17: =IFERROR(1-E17/D17,"") -> -0.01380814 | G17: 0.001918 | H17: 2.1e-05 | I17: 0.000104 | J17: 0.001024 | K17: 1e-05 | L17: 3.5e-05 | M17: =IFERROR(MAX(G17,J17),"") -> 0.001918 | N17: 0 | O17: 993 | P17: 3 | Q17: 0.112 | R17: =IFERROR(IF(M17/S17>$D$3,"Yes","No"),"") -> Yes | S17: =Dataset!$J$7 -> 0.1565 | T17: =IFERROR(M17/S17*100,"") -> 1.2255591
A18: Bolt Cutters 01 | B18: Mechanical | C18: No refinement | D18: 3410 | E18: 341 | F18: =IFERROR(1-E18/D18,"") -> 0.9 | G18: 0.120907 | H18: 0.001585 | I18: 0.003571 | J18: 0.012182 | K18: 0.002637 | L18: 0.008659 | M18: =IFERROR(MAX(G18,J18),"") -> 0.120907 | N18: 0 | O18: 0 | P18: 0 | Q18: 0.04 | R18: =IFERROR(IF(M18/S18>$D$3,"Yes","No"),"") -> Yes | S18: =Dataset!$J$8 -> 0.8175 | T18: =IFERROR(M18/S18*100,"") -> 14.789847
A19: Bolt Cutters 01 | B19: Mechanical | C19: Bidirectional refinement | D19: 3410 | E19: 1066 | F19: =IFERROR(1-E19/D19,"") -> 0.68739003 | G19: 0.006251 | H19: 0.00063 | I19: 0.00272 | J19: 0.006865 | K19: 0.001544 | L19: 0.004892 | M19: =IFERROR(MAX(G19,J19),"") -> 0.006865 | N19: 0 | O19: 141 | P19: 2 | Q19: 0.065 | R19: =IFERROR(IF(M19/S19>$D$3,"Yes","No"),"") -> No | S19: =Dataset!$J$8 -> 0.8175 | T19: =IFERROR(M19/S19*100,"") -> 0.83975535
A20: Drill 01 | B20: Mechanical | C20: No refinement | D20: 2926 | E20: 292 | F20: =IFERROR(1-E20/D20,"") -> 0.90020506 | G20: 0.045407 | H20: 0.001519 | I20: 0.004963 | J20: 0.013735 | K20: 0.001745 | L20: 0.005276 | M20: =IFERROR(MAX(G20,J20),"") -> 0.045407 | N20: 0 | O20: 0 | P20: 0 | Q20: 0.037 | R20: =IFERROR(IF(M20/S20>$D$3,"Yes","No"),"") -> Yes | S20: =Dataset!$J$9 -> 0.2654 | T20: =IFERROR(M20/S20*100,"") -> 17.108892
A21: Drill 01 | B21: Mechanical | C21: Bidirectional refinement | D21: 2926 | E21: 2730 | F21: =IFERROR(1-E21/D21,"") -> 0.066985646 | G21: 0.013249 | H21: 0.000334 | I21: 0.001865 | J21: 0.003009 | K21: 0.000133 | L21: 0.00083 | M21: =IFERROR(MAX(G21,J21),"") -> 0.013249 | N21: 0 | O21: 861 | P21: 3 | Q21: 0.129 | R21: =IFERROR(IF(M21/S21>$D$3,"Yes","No"),"") -> Yes | S21: =Dataset!$J$9 -> 0.2654 | T21: =IFERROR(M21/S21*100,"") -> 4.9920874
A22: Trilobite: Agnostid | B22: Organic | C22: No refinement | D22: 211874 | E22: 21172 | F22: =IFERROR(1-E22/D22,"") -> 0.90007268 | G22: 0.047435 | H22: 0.000548 | I22: 0.002304 | J22: 0.050117 | K22: 0.003483 | L22: 0.017823 | M22: =IFERROR(MAX(G22,J22),"") -> 0.050117 | N22: 0 | O22: 0 | P22: 0 | Q22: 2.707 | R22: =IFERROR(IF(M22/S22>$D$3,"Yes","No"),"") -> Yes | S22: =Dataset!$J$10 -> 2.2942 | T22: =IFERROR(M22/S22*100,"") -> 2.1845088
A23: Trilobite: Agnostid | B23: Organic | C23: Bidirectional refinement | D23: 211874 | E23: 42555 | F23: =IFERROR(1-E23/D23,"") -> 0.79914949 | G23: 0.055663 | H23: 0.00076 | I23: 0.003796 | J23: 0.021922 | K23: 0.001407 | L23: 0.005971 | M23: =IFERROR(MAX(G23,J23),"") -> 0.055663 | N23: 0 | O23: 4149 | P23: 3 | Q23: 9.923 | R23: =IFERROR(IF(M23/S23>$D$3,"Yes","No"),"") -> Yes | S23: =Dataset!$J$10 -> 2.2942 | T23: =IFERROR(M23/S23*100,"") -> 2.4262488
A24: Blastoid: Pentremites godani (PRI 70771) | B24: Organic | C24: No refinement | D24: 446670 | E24: 44633 | F24: =IFERROR(1-E24/D24,"") -> 0.90007612 | G24: 0.024506 | H24: 0.000375 | I24: 0.001435 | J24: 0.036757 | K24: 0.001138 | L24: 0.004789 | M24: =IFERROR(MAX(G24,J24),"") -> 0.036757 | N24: 0 | O24: 0 | P24: 0 | Q24: 5.725 | R24: =IFERROR(IF(M24/S24>$D$3,"Yes","No"),"") -> Yes | S24: =Dataset!$J$11 -> 1.878 | T24: =IFERROR(M24/S24*100,"") -> 1.9572417
A25: Blastoid: Pentremites godani (PRI 70771) | B25: Organic | C25: Bidirectional refinement | D25: 446670 | E25: 150195 | F25: =IFERROR(1-E25/D25,"") -> 0.66374505 | G25: 0.221384 | H25: 0.019596 | I25: 0.153286 | J25: 0.018332 | K25: 0.0007 | L25: 0.00312 | M25: =IFERROR(MAX(G25,J25),"") -> 0.221384 | N25: 0 | O25: 15225 | P25: 3 | Q25: 140.315 | R25: =IFERROR(IF(M25/S25>$D$3,"Yes","No"),"") -> Yes | S25: =Dataset!$J$11 -> 1.878 | T25: =IFERROR(M25/S25*100,"") -> 11.788285
A26: Vertebrate: T. rex tooth (PRI 55205) | B26: Organic | C26: No refinement | D26: 108958 | E26: 10890 | F26: =IFERROR(1-E26/D26,"") -> 0.90005323 | G26: 0.002859 | H26: 0.000309 | I26: 0.001 | J26: 0.003781 | K26: 0.000389 | L26: 0.001138 | M26: =IFERROR(MAX(G26,J26),"") -> 0.003781 | N26: 0 | O26: 0 | P26: 0 | Q26: 1.239 | R26: =IFERROR(IF(M26/S26>$D$3,"Yes","No"),"") -> No | S26: =Dataset!$J$12 -> 1.6142 | T26: =IFERROR(M26/S26*100,"") -> 0.23423368
A27: Vertebrate: T. rex tooth (PRI 55205) | B27: Organic | C27: Bidirectional refinement | D27: 108958 | E27: 10890 | F27: =IFERROR(1-E27/D27,"") -> 0.90005323 | G27: 0.002859 | H27: 0.000309 | I27: 0.001 | J27: 0.003781 | K27: 0.000389 | L27: 0.001138 | M27: =IFERROR(MAX(G27,J27),"") -> 0.003781 | N27: 0 | O27: 0 | P27: 1 | Q27: 0.345 | R27: =IFERROR(IF(M27/S27>$D$3,"Yes","No"),"") -> No | S27: =Dataset!$J$12 -> 1.6142 | T27: =IFERROR(M27/S27*100,"") -> 0.23423368
A28: Loewe (lion) | B28: Organic | C28: No refinement | D28: 405680 | E28: 40563 | F28: =IFERROR(1-E28/D28,"") -> 0.90001232 | G28: 0.020625 | H28: 0.00099 | I28: 0.003847 | J28: 0.050376 | K28: 0.001406 | L28: 0.004999 | M28: =IFERROR(MAX(G28,J28),"") -> 0.050376 | N28: 0 | O28: 0 | P28: 0 | Q28: 8.074 | R28: =IFERROR(IF(M28/S28>$D$3,"Yes","No"),"") -> Yes | S28: =Dataset!$J$13 -> 4.8654 | T28: =IFERROR(M28/S28*100,"") -> 1.0353928
A29: Loewe (lion) | B29: Organic | C29: Bidirectional refinement | D29: 405680 | E29: 98032 | F29: =IFERROR(1-E29/D29,"") -> 0.75835141 | G29: 0.365014 | H29: 0.013302 | I29: 0.108886 | J29: 0.035891 | K29: 0.001038 | L29: 0.003859 | M29: =IFERROR(MAX(G29,J29),"") -> 0.365014 | N29: 0 | O29: 4044 | P29: 3 | Q29: 80.122 | R29: =IFERROR(IF(M29/S29>$D$3,"Yes","No"),"") -> Yes | S29: =Dataset!$J$13 -> 4.8654 | T29: =IFERROR(M29/S29*100,"") -> 7.5022403
A30: Weisshai Great White Shark | B30: Scanned | C30: No refinement | D30: 5912 | E30: 591 | F30: =IFERROR(1-E30/D30,"") -> 0.90003383 | G30: 0 | H30: 0 | I30: 0 | J30: 0.020442 | K30: 0.003538 | L30: 0.009479 | M30: =IFERROR(MAX(G30,J30),"") -> 0.020442 | N30: 0 | O30: 0 | P30: 0 | Q30: 0.061 | R30: =IFERROR(IF(M30/S30>$D$3,"Yes","No"),"") -> Yes | S30: =Dataset!$J$14 -> 0.2327 | T30: =IFERROR(M30/S30*100,"") -> 8.7847013
A31: Weisshai Great White Shark | B31: Scanned | C31: Bidirectional refinement | D31: 5912 | E31: 5129 | F31: =IFERROR(1-E31/D31,"") -> 0.13244249 | G31: 0.008328 | H31: 0.000272 | I31: 0.001674 | J31: 0.002315 | K31: 0.000264 | L31: 0.001334 | M31: =IFERROR(MAX(G31,J31),"") -> 0.008328 | N31: 0 | O31: 10386 | P31: 3 | Q31: 0.267 | R31: =IFERROR(IF(M31/S31>$D$3,"Yes","No"),"") -> Yes | S31: =Dataset!$J$14 -> 0.2327 | T31: =IFERROR(M31/S31*100,"") -> 3.5788569
A32: Vegetable Garden | B32: Scanned | C32: No refinement | D32: 16694 | E32: 1669 | F32: =IFERROR(1-E32/D32,"") -> 0.90002396 | G32: 0 | H32: 0 | I32: 0 | J32: 0.021685 | K32: 0.004159 | L32: 0.015282 | M32: =IFERROR(MAX(G32,J32),"") -> 0.021685 | N32: 0 | O32: 0 | P32: 0 | Q32: 0.181 | R32: =IFERROR(IF(M32/S32>$D$3,"Yes","No"),"") -> Yes | S32: =Dataset!$J$15 -> 0.3029 | T32: =IFERROR(M32/S32*100,"") -> 7.1591284
A33: Vegetable Garden | B33: Scanned | C33: Bidirectional refinement | D33: 16694 | E33: 11921 | F33: =IFERROR(1-E33/D33,"") -> 0.28591111 | G33: 0.006045 | H33: 0.000111 | I33: 0.000592 | J33: 0.003023 | K33: 0.000306 | L33: 0.001476 | M33: =IFERROR(MAX(G33,J33),"") -> 0.006045 | N33: 0 | O33: 24277 | P33: 3 | Q33: 0.704 | R33: =IFERROR(IF(M33/S33>$D$3,"Yes","No"),"") -> Yes | S33: =Dataset!$J$15 -> 0.3029 | T33: =IFERROR(M33/S33*100,"") -> 1.9957082
A34: Curled Rat netsuke, test scan | B34: Scanned | C34: No refinement | D34: 63998 | E34: 6378 | F34: =IFERROR(1-E34/D34,"") -> 0.90034064 | G34: 0.004009 | H34: 0.000363 | I34: 0.001331 | J34: 0.005144 | K34: 0.00054 | L34: 0.00166 | M34: =IFERROR(MAX(G34,J34),"") -> 0.005144 | N34: 0 | O34: 0 | P34: 0 | Q34: 0.646 | R34: =IFERROR(IF(M34/S34>$D$3,"Yes","No"),"") -> Yes | S34: =Dataset!$J$16 -> 0.4564 | T34: =IFERROR(M34/S34*100,"") -> 1.1270815
A35: Curled Rat netsuke, test scan | B35: Scanned | C35: Bidirectional refinement | D35: 63998 | E35: 6530 | F35: =IFERROR(1-E35/D35,"") -> 0.89796556 | G35: 0.004009 | H35: 0.000358 | I35: 0.001321 | J35: 0.004231 | K35: 0.000541 | L35: 0.001674 | M35: =IFERROR(MAX(G35,J35),"") -> 0.004231 | N35: 0 | O35: 9 | P35: 2 | Q35: 0.81 | R35: =IFERROR(IF(M35/S35>$D$3,"Yes","No"),"") -> No | S35: =Dataset!$J$16 -> 0.4564 | T35: =IFERROR(M35/S35*100,"") -> 0.92703769
A36: Stanford Bunny (reconstruction) | B36: Scanned | C36: No refinement | D36: 69451 | E36: 6945 | F36: =IFERROR(1-E36/D36,"") -> 0.90000144 | G36: 0.000418 | H36: 5.9e-05 | I36: 0.000147 | J36: 0.000351 | K36: 4.6e-05 | L36: 0.000122 | M36: =IFERROR(MAX(G36,J36),"") -> 0.000418 | N36: 0 | O36: 0 | P36: 0 | Q36: 0.483 | R36: =IFERROR(IF(M36/S36>$D$3,"Yes","No"),"") -> No | S36: =Dataset!$J$17 -> 0.2502 | T36: =IFERROR(M36/S36*100,"") -> 0.16706635
A37: Stanford Bunny (reconstruction) | B37: Scanned | C37: Bidirectional refinement | D37: 69451 | E37: 6945 | F37: =IFERROR(1-E37/D37,"") -> 0.90000144 | G37: 0.000418 | H37: 5.9e-05 | I37: 0.000147 | J37: 0.000351 | K37: 4.6e-05 | L37: 0.000122 | M37: =IFERROR(MAX(G37,J37),"") -> 0.000418 | N37: 0 | O37: 0 | P37: 1 | Q37: 0.159 | R37: =IFERROR(IF(M37/S37>$D$3,"Yes","No"),"") -> No | S37: =Dataset!$J$17 -> 0.2502 | T37: =IFERROR(M37/S37*100,"") -> 0.16706635
A38: Stanford Armadillo (reconstruction) | B38: Scanned | C38: No refinement | D38: 345944 | E38: 34594 | F38: =IFERROR(1-E38/D38,"") -> 0.90000116 | G38: 0.174982 | H38: 0.023869 | I38: 0.058805 | J38: 0.165635 | K38: 0.018964 | L38: 0.04939 | M38: =IFERROR(MAX(G38,J38),"") -> 0.174982 | N38: 0 | O38: 0 | P38: 0 | Q38: 3.863 | R38: =IFERROR(IF(M38/S38>$D$3,"Yes","No"),"") -> No | S38: =Dataset!$J$18 -> 228.8037 | T38: =IFERROR(M38/S38*100,"") -> 0.07647691
A39: Stanford Armadillo (reconstruction) | B39: Scanned | C39: Bidirectional refinement | D39: 345944 | E39: 34594 | F39: =IFERROR(1-E39/D39,"") -> 0.90000116 | G39: 0.174982 | H39: 0.023869 | I39: 0.058805 | J39: 0.165635 | K39: 0.018964 | L39: 0.04939 | M39: =IFERROR(MAX(G39,J39),"") -> 0.174982 | N39: 0 | O39: 0 | P39: 1 | Q39: 1.497 | R39: =IFERROR(IF(M39/S39>$D$3,"Yes","No"),"") -> No | S39: =Dataset!$J$18 -> 228.8037 | T39: =IFERROR(M39/S39*100,"") -> 0.07647691
A40: Electrocardiograph Machine (AI-generated) | B40: Generated | C40: No refinement | D40: 1869988 | E40: 186998 | F40: =IFERROR(1-E40/D40,"") -> 0.90000043 | G40: 0 | H40: 0 | I40: 0 | J40: 0.0188 | K40: 0.002406 | L40: 0.005335 | M40: =IFERROR(MAX(G40,J40),"") -> 0.0188 | N40: 0 | O40: 0 | P40: 0 | Q40: 25.439 | R40: =IFERROR(IF(M40/S40>$D$3,"Yes","No"),"") -> No | S40: =Dataset!$J$19 -> 2.3606 | T40: =IFERROR(M40/S40*100,"") -> 0.79640769
A41: Electrocardiograph Machine (AI-generated) | B41: Generated | C41: Bidirectional refinement | D41: 1869988 | E41: 186998 | F41: =IFERROR(1-E41/D41,"") -> 0.90000043 | G41: 0 | H41: 0 | I41: 0 | J41: 0.0188 | K41: 0.002406 | L41: 0.005335 | M41: =IFERROR(MAX(G41,J41),"") -> 0.0188 | N41: 0 | O41: 0 | P41: 1 | Q41: 12.962 | R41: =IFERROR(IF(M41/S41>$D$3,"Yes","No"),"") -> No | S41: =Dataset!$J$19 -> 2.3606 | T41: =IFERROR(M41/S41*100,"") -> 0.79640769
...

Sheet Exp_C_Masked
A1: Experiment C — Masked simplification
A2: Can split->decimate->merge preserve a user-designated region while simplifying the rest?
A4: Case | B4: Description | C4: Source tris | D4: Important faces | E4: Important % | F4: Unmasked result tris | G4: Unmasked global reduction % | H4: Unmasked E_imp max | I4: Unmasked E_imp mean | J4: Unmasked E_imp p95 | K4: Unmasked E_rest max | L4: Unmasked E_rest mean | M4: Unmasked E_rest p95 | N4: Masked result tris | O4: Masked global reduction % | P4: Masked unprotected tris before | Q4: Masked unprotected tris after | R4: Masked zone reduction % | S4: Masked E_imp max | T4: Masked E_imp mean | U4: Masked E_imp p95 | V4: Masked E_rest max | W4: Masked E_rest mean | X4: Masked E_rest p95
A5: case1_removed_bump | B5: Disconnected satellite region completely removed from the result. | C5: 3280 | D5: 240 | E5: =D5/C5 -> 0.073170732 | F5: 328 | G5: =1-F5/C5 -> 0.9 | H5: 0.011058 | I5: 0.003427 | J5: 0.00902 | K5: 0.008945 | L5: 0.003164 | M5: 0.006621 | N5: 544 | O5: =1-N5/C5 -> 0.83414634 | P5: 3040 | Q5: 304 | R5: =IFERROR(1-Q5/P5,0) -> 0.9 | S5: 0 | T5: 0 | U5: 0 | V5: 0.008356 | W5: 0.002848 | X5: 0.006192
A6: case2_partial_detail | B6: Connected raised bump, only its outer ring flattened (partial removal). | C6: 6960 | D6: 780 | E6: =D6/C6 -> 0.11206897 | F6: 696 | G6: =1-F6/C6 -> 0.9 | H6: 0.006292 | I6: 0.001476 | J6: 0.003556 | K6: 0.004506 | L6: 0.001321 | M6: 0.00295 | N6: 1398 | O6: =1-N6/C6 -> 0.79913793 | P6: 6180 | Q6: 618 | R6: =IFERROR(1-Q6/P6,0) -> 0.9 | S6: 0 | T6: 0 | U6: 0 | V6: 0.004945 | W6: 0.001455 | X6: 0.00323
A7: case3_surface_relief | B7: Small, localized bump on an otherwise continuous surface (no handcrafted result). | C7: 6960 | D7: 36 | E7: =D7/C7 -> 0.0051724138 | F7: 696 | G7: =1-F7/C7 -> 0.9 | H7: 0.005657 | I7: 0.00135 | J7: 0.004084 | K7: 0.004506 | L7: 0.001213 | M7: 0.002725 | N7: 734 | O7: =1-N7/C7 -> 0.89454023 | P7: 6924 | Q7: 692 | R7: =IFERROR(1-Q7/P7,0) -> 0.90005777 | S7: 0 | T7: 0 | U7: 0 | V7: 0.003601 | W7: 0.001171 | X7: 0.00262
A8: case4_multi_region | B8: Three raised details of decreasing size/prominence at different locations. | C8: 9520 | D8: 1000 | E8: =D8/C8 -> 0.10504202 | F8: 952 | G8: =1-F8/C8 -> 0.9 | H8: 0.005764 | I8: 0.001183 | J8: 0.003214 | K8: 0.003445 | L8: 0.001018 | M8: 0.002382 | N8: 1872 | O8: =1-N8/C8 -> 0.80336134 | P8: 8520 | Q8: 852 | R8: =IFERROR(1-Q8/P8,0) -> 0.9 | S8: 0 | T8: 0 | U8: 0 | V8: 0.003885 | W8: 0.001052 | X8: 0.002421

Sheet Exp_D_Threshold_Sensitivity
A1: Experiment D — Error-threshold sensitivity
A2: As the error threshold tightens, expect: more protection -> less reduction -> less geometric error.
A4: Model | B4: Threshold % | C4: Source tris | D4: Result tris | E4: Reduction % | F4: Iterations | G4: Points added | H4: E_max final | I4: E_mean final | J4: E_p95 final
A5: Carrot Cake | B5: 0.25 | C5: 13790 | D5: 13346 | E5: =IFERROR(1-D5/C5,"") -> 0.032197244 | F5: 3 | G5: 4757 | H5: 0.004065 | I5: 4.5e-05 | J5: 0.000294
A6: Carrot Cake | B6: 0.5 | C6: 13790 | D6: 9089 | E6: =IFERROR(1-D6/C6,"") -> 0.3408992 | F6: 3 | G6: 2301 | H6: 0.017493 | I6: 0.000239 | J6: 0.000932
A7: Carrot Cake | B7: 1 | C7: 13790 | D7: 5231 | E7: =IFERROR(1-D7/C7,"") -> 0.62066715 | F7: 3 | G7: 865 | H7: 0.007995 | I7: 0.000394 | J7: 0.001445
A8: Carrot Cake | B8: 2 | C8: 13790 | D8: 3672 | E8: =IFERROR(1-D8/C8,"") -> 0.73372009 | F8: 3 | G8: 345 | H8: 0.010472 | I8: 0.000569 | J8: 0.002021
A9: Carrot Cake | B9: 5 | C9: 13790 | D9: 2874 | E9: =IFERROR(1-D9/C9,"") -> 0.79158811 | F9: 3 | G9: 32 | H9: 0.019372 | I9: 0.00092 | J9: 0.003562
A10: Trilobite: Agnostid | B10: 0.25 | C10: 211874 | D10: 96954 | E10: =IFERROR(1-D10/C10,"") -> 0.54239784 | F10: 3 | G10: 24710 | H10: 0.194294 | I10: 0.001703 | J10: 0.002216
A11: Trilobite: Agnostid | B11: 0.5 | C11: 211874 | D11: 66527 | E11: =IFERROR(1-D11/C11,"") -> 0.68600678 | F11: 3 | G11: 12703 | H11: 0.099413 | I11: 0.001215 | J11: 0.003937
A12: Trilobite: Agnostid | B12: 1 | C12: 211874 | D12: 42555 | E12: =IFERROR(1-D12/C12,"") -> 0.79914949 | F12: 3 | G12: 4149 | H12: 0.055663 | I12: 0.001299 | J12: 0.005793
A13: Trilobite: Agnostid | B13: 2 | C13: 211874 | D13: 33178 | E13: =IFERROR(1-D13/C13,"") -> 0.84340693 | F13: 2 | G13: 194 | H13: 0.041446 | I13: 0.002427 | J13: 0.011776
A14: Trilobite: Agnostid | B14: 5 | C14: 211874 | D14: 21172 | E14: =IFERROR(1-D14/C14,"") -> 0.90007268 | F14: 1 | G14: 0 | H14: 0.050117 | I14: 0.003216 | J14: 0.016779
A15: Loewe (lion) | B15: 0.25 | C15: 405680 | D15: 125308 | E15: =IFERROR(1-D15/C15,"") -> 0.69111615 | F15: 3 | G15: 9795 | H15: 0.396172 | I15: 0.003674 | J15: 0.004656
A16: Loewe (lion) | B16: 0.5 | C16: 405680 | D16: 106515 | E16: =IFERROR(1-D16/C16,"") -> 0.73744084 | F16: 3 | G16: 5707 | H16: 0.359226 | I16: 0.003218 | J16: 0.004951
... A29: Electrocardiograph Machine (AI-generated) | B29: 5 | C29: 1869988 | D29: 186998 | E29: =IFERROR(1-D29/C29,"") -> 0.90000043 | F29: 1 | G29: 0 | H29: 0.0188 | I29: 0.002187 | J29: 0.005206

Sheet Exp_E_Reduction_Sensitivity
A1: Experiment E — Requested-reduction sensitivity
A2: The error-guided refinement never changes the reduction target; it only grows protection. Global reduction can end up well below the request; unprotected-zone reduction should stay close to it.
A4: Model | B4: Requested reduction % | C4: Source tris | D4: Result tris | E4: Actual global reduction % | F4: Unprotected tris before | G4: Unprotected tris after | H4: Unprotected zone reduction % | I4: E_max | J4: Iterations
A5: Carrot Cake | B5: 50 | C5: 13790 | D5: 6894 | E5: =IFERROR(1-D5/C5,"") -> 0.50007252 | F5: 13790 | G5: 6894 | H5: =IFERROR(1-G5/F5,"") -> 0.50007252 | I5: 0.00131 | J5: 1
A6: Carrot Cake | B6: 70 | C6: 13790 | D6: 6484 | E6: =IFERROR(1-D6/C6,"") -> 0.52980421 | F6: 12766 | G6: 3829 | H6: =IFERROR(1-G6/F6,"") -> 0.70006267 | I6: 0.003314 | J6: 3
A7: Carrot Cake | B7: 80 | C7: 13790 | D7: 6452 | E7: =IFERROR(1-D7/C7,"") -> 0.53212473 | F7: 12042 | G7: 2408 | H7: =IFERROR(1-G7/F7,"") -> 0.80003322 | I7: 0.003296 | J7: 2
A8: Carrot Cake | B8: 90 | C8: 13790 | D8: 5231 | E8: =IFERROR(1-D8/C8,"") -> 0.62066715 | F8: 11261 | G8: 1126 | H8: =IFERROR(1-G8/F8,"") -> 0.90000888 | I8: 0.007995 | J8: 3
A9: Carrot Cake | B9: 95 | C9: 13790 | D9: 6358 | E9: =IFERROR(1-D9/C9,"") -> 0.53894126 | F9: 9834 | G9: 491 | H9: =IFERROR(1-G9/F9,"") -> 0.95007118 | I9: 0.023932 | J9: 3
A10: Trilobite: Agnostid | B10: 50 | C10: 211874 | D10: 105936 | E10: =IFERROR(1-D10/C10,"") -> 0.50000472 | F10: 211874 | G10: 105936 | H10: =IFERROR(1-G10/F10,"") -> 0.50000472 | I10: 0.007433 | J10: 1
A11: Trilobite: Agnostid | B11: 70 | C11: 211874 | D11: 63562 | E11: =IFERROR(1-D11/C11,"") -> 0.70000094 | F11: 211874 | G11: 63562 | H11: =IFERROR(1-G11/F11,"") -> 0.70000094 | I11: 0.007447 | J11: 1
A12: Trilobite: Agnostid | B12: 80 | C12: 211874 | D12: 42372 | E12: =IFERROR(1-D12/C12,"") -> 0.80001322 | F12: 211874 | G12: 42374 | H12: =IFERROR(1-G12/F12,"") -> 0.80000378 | I12: 0.007856 | J12: 1
A13: Trilobite: Agnostid | B13: 90 | C13: 211874 | D13: 42555 | E13: =IFERROR(1-D13/C13,"") -> 0.79914949 | F13: 202363 | G13: 20236 | H13: =IFERROR(1-G13/F13,"") -> 0.90000148 | I13: 0.055663 | J13: 3
A14: Trilobite: Agnostid | B14: 95 | C14: 211874 | D14: 36457 | E14: =IFERROR(1-D14/C14,"") -> 0.82793075 | F14: 196329 | G14: 9815 | H14: =IFERROR(1-G14/F14,"") -> 0.95000739 | I14: 0.192702 | J14: 3
A15: Loewe (lion) | B15: 50 | C15: 405680 | D15: 202840 | E15: =IFERROR(1-D15/C15,"") -> 0.5 | F15: 405680 | G15: 202840 | H15: =IFERROR(1-G15/F15,"") -> 0.5 | I15: 0.003247 | J15: 1
A16: Loewe (lion) | B16: 70 | C16: 405680 | D16: 121695 | E16: =IFERROR(1-D16/C16,"") -> 0.70002218 | F16: 405680 | G16: 121704 | H16: =IFERROR(1-G16/F16,"") -> 0.7 | I16: 0.041449 | J16: 1
... A29: Electrocardiograph Machine (AI-generated) | B29: 95 | C29: 1869988 | D29: 265646 | E29: =IFERROR(1-D29/C29,"") -> 0.8579424 | F29: 1869984 | G29: 93499 | H29: =IFERROR(1-G29/F29,"") -> 0.95000011 | I29: 0.023574 | J29: 2

Sheet Engine_Comparison
A1: Engine comparison — vtkDecimatePro vs. vtkQuadricDecimation
A2: Same models/parameters, both engines. Not to declare a winner - to show the pipeline is engine-independent.
A4: Model | B4: Engine | C4: Requested reduction % | D4: Source tris | E4: Result tris | F4: Actual reduction % | G4: E_max | H4: E_mean | I4: Runtime (s) | J4: Iterations | K4: Protected vertices | L4: Boundary edges found (interface issues)
A5: Sculpture of man and woman (Egyptian excavation) | B5: DecimatePro | C5: 90 | D5: 59996 | E5: 14124 | F5: =IFERROR(1-E5/D5,"") -> 0.76458431 | G5: 3.249123 | H5: 0.165863 | I5: 0.377 | J5: 0 | K5: 0 | L5: 4286
A6: Sculpture of man and woman (Egyptian excavation) | B6: QEM | C6: 90 | D6: 59996 | E6: 5999 | F6: =IFERROR(1-E6/D6,"") -> 0.90001 | G6: 1.897487 | H6: 0.170162 | I6: 0.621 | J6: 0 | K6: 0 | L6: 4285
A7: 1993.165 Statuette of a Woman: "The Stargazer" | B7: DecimatePro | C7: 90 | D7: 15000 | E7: 5120 | F7: =IFERROR(1-E7/D7,"") -> 0.65866667 | G7: 0.254858 | H7: 0.01551 | I7: 0.092 | J7: 0 | K7: 0 | L7: 704
A8: 1993.165 Statuette of a Woman: "The Stargazer" | B8: QEM | C8: 90 | D8: 15000 | E8: 1500 | F8: =IFERROR(1-E8/D8,"") -> 0.9 | G8: 0.088753 | H8: 0.013436 | I8: 0.124 | J8: 0 | K8: 0 | L8: 704
A9: Statuette of a Woman in Hunting Clothes | B9: DecimatePro | C9: 90 | D9: 130504 | E9: 25864 | F9: =IFERROR(1-E9/D9,"") -> 0.8018145 | G9: 0.773909 | H9: 0.060575 | I9: 0.769 | J9: 0 | K9: 0 | L9: 7466
A10: Statuette of a Woman in Hunting Clothes | B10: QEM | C10: 90 | D10: 130504 | E10: 13049 | F10: =IFERROR(1-E10/D10,"") -> 0.90001073 | G10: 0.359945 | H10: 0.04011 | I10: 1.309 | J10: 0 | K10: 0 | L10: 7465
A11: Barrel 03 | B11: DecimatePro | C11: 90 | D11: 1473 | E11: 1253 | F11: =IFERROR(1-E11/D11,"") -> 0.14935506 | G11: 0.006029 | H11: 0.000637 | I11: 0.01 | J11: 0 | K11: 0 | L11: 747
A12: Barrel 03 | B12: QEM | C12: 90 | D12: 1473 | E12: 146 | F12: =IFERROR(1-E12/D12,"") -> 0.90088255 | G12: 7.915454 | H12: 0.063259 | I12: 0.021 | J12: 0 | K12: 0 | L12: 156
A13: Carrot Cake | B13: DecimatePro | C13: 90 | D13: 13790 | E13: 9762 | F13: =IFERROR(1-E13/D13,"") -> 0.29209572 | G13: 0.004109 | H13: 8.3e-05 | I13: 0.112 | J13: 0 | K13: 0 | L13: 4222
A14: Carrot Cake | B14: QEM | C14: 90 | D14: 13790 | E14: 1376 | F14: =IFERROR(1-E14/D14,"") -> 0.90021755 | G14: 0.020696 | H14: 0.001061 | I14: 0.185 | J14: 0 | K14: 0 | L14: 1662
A15: Carved Wooden Elephant | B15: DecimatePro | C15: 90 | D15: 2752 | E15: 1654 | F15: =IFERROR(1-E15/D15,"") -> 0.39898256 | G15: 0.005189 | H15: 0.000173 | I15: 0.018 | J15: 0 | K15: 0 | L15: 562
A16: Carved Wooden Elephant | B16: QEM | C16: 90 | D16: 2752 | E16: 273 | F16: =IFERROR(1-E16/D16,"") -> 0.90079942 | G16: 0.010291 | H16: 0.001566 | I16: 0.033 | J16: 0 | K16: 0 | L16: 281
... A42: Realistic Heart (AI-generated) | B42: QEM | C42: 90 | D42: 31400 | E42: 3140 | F42: =IFERROR(1-E42/D42,"") -> 0.9 | G42: 0.128813 | H42: 0.023364 | I42: 0.352 | J42: 0 | K42: 0 | L42: 9420

Sheet UV_Seam_Detection
A1: UV seam detection and geometric protection
A2: A: does the detector find the intended seam? B: does turning protection on stop those vertices from collapsing? Reminder for the paper: UV coordinate DATA is not currently preserved after the masked merge/weld step whenever any mask is active (verified empirically) - report that as a limitation, not as 'UV preserved'.
A4: Model | B4: Expected seam vertices | C4: Detected seam vertices | D4: Precision | E4: Recall | F4: UV protection ON? | G4: Seam vertices collapsed? | H4: UV coord. data preserved after merge?
A5: grid_no_seam_control | B5: 0 | C5: 0 | D5: =IFERROR(C5/(C5+MAX(C5-B5,0)),"") | E5: =IFERROR(MIN(C5,B5)/B5,"") | F5: No | G5: No | H5: Yes
A6: grid_no_seam_control | B6: 0 | C6: 0 | D6: =IFERROR(C6/(C6+MAX(C6-B6,0)),"") | E6: =IFERROR(MIN(C6,B6)/B6,"") | F6: Yes | G6: No | H6: Yes
A7: grid_1seam_small | B7: 12 | C7: 12 | D7: =IFERROR(C7/(C7+MAX(C7-B7,0)),"") -> 1 | E7: =IFERROR(MIN(C7,B7)/B7,"") -> 1 | F7: No | G7: No | H7: Yes
A8: grid_1seam_small | B8: 12 | C8: 12 | D8: =IFERROR(C8/(C8+MAX(C8-B8,0)),"") -> 1 | E8: =IFERROR(MIN(C8,B8)/B8,"") -> 1 | F8: Yes | G8: No | H8: No
A9: grid_1seam_medium | B9: 20 | C9: 20 | D9: =IFERROR(C9/(C9+MAX(C9-B9,0)),"") -> 1 | E9: =IFERROR(MIN(C9,B9)/B9,"") -> 1 | F9: No | G9: Yes | H9: Yes
A10: grid_1seam_medium | B10: 20 | C10: 20 | D10: =IFERROR(C10/(C10+MAX(C10-B10,0)),"") -> 1 | E10: =IFERROR(MIN(C10,B10)/B10,"") -> 1 | F10: Yes | G10: No | H10: No
A11: grid_1seam_large | B11: 32 | C11: 32 | D11: =IFERROR(C11/(C11+MAX(C11-B11,0)),"") -> 1 | E11: =IFERROR(MIN(C11,B11)/B11,"") -> 1 | F11: No | G11: Yes | H11: Yes
A12: grid_1seam_large | B12: 32 | C12: 32 | D12: =IFERROR(C12/(C12+MAX(C12-B12,0)),"") -> 1 | E12: =IFERROR(MIN(C12,B12)/B12,"") -> 1 | F12: Yes | G12: No | H12: No
A13: grid_2seams_multi | B13: 32 | C13: 32 | D13: =IFERROR(C13/(C13+MAX(C13-B13,0)),"") -> 1 | E13: =IFERROR(MIN(C13,B13)/B13,"") -> 1 | F13: No | G13: No | H13: Yes
A14: grid_2seams_multi | B14: 32 | C14: 32 | D14: =IFERROR(C14/(C14+MAX(C14-B14,0)),"") -> 1 | E14: =IFERROR(MIN(C14,B14)/B14,"") -> 1 | F14: Yes | G14: No | H14: No
A15: grid_1seam_thin_strip | B15: 40 | C15: 40 | D15: =IFERROR(C15/(C15+MAX(C15-B15,0)),"") -> 1 | E15: =IFERROR(MIN(C15,B15)/B15,"") -> 1 | F15: No | G15: Yes | H15: Yes
A16: grid_1seam_thin_strip | B16: 40 | C16: 40 | D16: =IFERROR(C16/(C16+MAX(C16-B16,0)),"") -> 1 | E16: =IFERROR(MIN(C16,B16)/B16,"") -> 1 | F16: Yes | G16: No | H16: No
D17: =IFERROR(C17/(C17+MAX(C17-B17,0)),"") | E17: =IFERROR(MIN(C17,B17)/B17,"")
D18: =IFERROR(C18/(C18+MAX(C18-B18,0)),"") | E18: =IFERROR(MIN(C18,B18)/B18,"")
D19: =IFERROR(C19/(C19+MAX(C19-B19,0)),"") | E19: =IFERROR(MIN(C19,B19)/B19,"")

Sheet Validity_Checks
A1: Validity checks — post-simplification mesh integrity
A2: Run after every simplification you evaluate. Important because the boundary-gap repair stage fan-triangulates by hand (see remesh_core.py's _stitch_residual_boundary_gaps).
A4: Model | B4: Config | C4: Faces | D4: Vertices | E4: Duplicate vertices | F4: Boundary edges | G4: Non-manifold edges | H4: Degenerate faces | I4: Connected components | J4: Watertight?
A5: Sculpture of man and woman (Egyptian excavation) | B5: Before (raw load) | C5: 59996 | D5: 32175 | E5: 4284 | F5: 4286 | G5: 0 | H5: 0 | I5: 34 | J5: =IFERROR(IF(F5=0,"Yes","No"),"") -> No
A6: Sculpture of man and woman (Egyptian excavation) | B6: After (default pipeline, 90%) | C6: 20228 | D6: 10116 | E6: 0 | F6: 0 | G6: 0 | H6: 0 | I6: 1 | J6: =IFERROR(IF(F6=0,"Yes","No"),"") -> Yes
A7: 1993.165 Statuette of a Woman: "The Stargazer" | B7: Before (raw load) | C7: 15000 | D7: 7856 | E7: 704 | F7: 704 | G7: 0 | H7: 0 | I7: 4 | J7: =IFERROR(IF(F7=0,"Yes","No"),"") -> No
A8: 1993.165 Statuette of a Woman: "The Stargazer" | B8: After (default pipeline, 90%) | C8: 6312 | D8: 3158 | E8: 0 | F8: 0 | G8: 0 | H8: 0 | I8: 1 | J8: =IFERROR(IF(F8=0,"Yes","No"),"") -> Yes
A9: Statuette of a Woman in Hunting Clothes | B9: Before (raw load) | C9: 130504 | D9: 69037 | E9: 7457 | F9: 7466 | G9: 0 | H9: 0 | I9: 67 | J9: =IFERROR(IF(F9=0,"Yes","No"),"") -> No
A10: Statuette of a Woman in Hunting Clothes | B10: After (default pipeline, 90%) | C10: 36140 | D10: 18063 | E10: 0 | F10: 0 | G10: 0 | H10: 0 | I10: 1 | J10: =IFERROR(IF(F10=0,"Yes","No"),"") -> Yes
A11: Barrel 03 | B11: Before (raw load) | C11: 1473 | D11: 1126 | E11: 730 | F11: 749 | G11: 0 | H11: 0 | I11: 17 | J11: =IFERROR(IF(F11=0,"Yes","No"),"") -> No
A12: Barrel 03 | B12: After (default pipeline, 90%) | C12: 1386 | D12: 697 | E12: 0 | F12: 0 | G12: 0 | H12: 0 | I12: 2 | J12: =IFERROR(IF(F12=0,"Yes","No"),"") -> Yes
A13: Carrot Cake | B13: Before (raw load) | C13: 13790 | D13: 9211 | E13: 4209 | F13: 4222 | G13: 0 | H13: 0 | I13: 289 | J13: =IFERROR(IF(F13=0,"Yes","No"),"") -> No
A14: Carrot Cake | B14: After (default pipeline, 90%) | C14: 11708 | D14: 5854 | E14: 0 | F14: 0 | G14: 0 | H14: 0 | I14: 1 | J14: =IFERROR(IF(F14=0,"Yes","No"),"") -> Yes
A15: Carved Wooden Elephant | B15: Before (raw load) | C15: 2752 | D15: 1664 | E15: 554 | F15: 562 | G15: 0 | H15: 0 | I15: 9 | J15: =IFERROR(IF(F15=0,"Yes","No"),"") -> No
A16: Carved Wooden Elephant | B16: After (default pipeline, 90%) | C16: 2036 | D16: 1016 | E16: 0 | F16: 0 | G16: 0 | H16: 0 | I16: 1 | J16: =IFERROR(IF(F16=0,"Yes","No"),"") -> Yes
... A42: Realistic Heart (AI-generated) | B42: After (default pipeline, 90%) | C42: 21252 | D42: 10588 | E42: 0 | F42: 0 | G42: 0 | H42: 0 | I42: 1 | J42: =IFERROR(IF(F42=0,"Yes","No"),"") -> Yes

Sheet Runtime
A1: Runtime overhead
A2: How much computational overhead does bidirectional validation introduce? T_Decimation/T_Error/T_Repair need remesh_core.py instrumented with timers if you want the breakdown; T_Total alone can be measured today with a stopwatch around run_decimation_pipeline().
A4: Model | B4: Source tris | C4: Config | D4: T_Total (s) | E4: T_Decimation (s) | F4: T_Error (s) | G4: T_Repair (s) | H4: T_Other (s)
A5: Sculpture of man and woman (Egyptian excavation) | B5: 59996 | C5: Default pipeline (DecimatePro, 90%, UV+auto-error protection) | D5: 0.4565 | E5: 0.1942 | H5: =IFERROR(D5-SUM(E5:G5),"") -> 0.2623
A6: 1993.165 Statuette of a Woman: "The Stargazer" | B6: 15000 | C6: Default pipeline (DecimatePro, 90%, UV+auto-error protection) | D6: 0.1956 | E6: 0.047 | H6: =IFERROR(D6-SUM(E6:G6),"") -> 0.1486
A7: Statuette of a Woman in Hunting Clothes | B7: 130504 | C7: Default pipeline (DecimatePro, 90%, UV+auto-error protection) | D7: 0.9209 | E7: 0.3898 | H7: =IFERROR(D7-SUM(E7:G7),"") -> 0.5311
A8: Barrel 03 | B8: 1473 | C8: Default pipeline (DecimatePro, 90%, UV+auto-error protection) | D8: 0.0194 | E8: 0.0099 | H8: =IFERROR(D8-SUM(E8:G8),"") -> 0.0095
A9: Carrot Cake | B9: 13790 | C9: Default pipeline (DecimatePro, 90%, UV+auto-error protection) | D9: 0.2646 | E9: 0.0374 | H9: =IFERROR(D9-SUM(E9:G9),"") -> 0.2272
A10: Carved Wooden Elephant | B10: 2752 | C10: Default pipeline (DecimatePro, 90%, UV+auto-error protection) | D10: 0.0538 | E10: 0.0143 | H10: =IFERROR(D10-SUM(E10:G10),"") -> 0.0395
A11: Bolt Cutters 01 | B11: 3410 | C11: Default pipeline (DecimatePro, 90%, UV+auto-error protection) | D11: 0.041 | E11: 0.0198 | H11: =IFERROR(D11-SUM(E11:G11),"") -> 0.0212
A12: Drill 01 | B12: 2926 | C12: Default pipeline (DecimatePro, 90%, UV+auto-error protection) | D12: 0.0936 | E12: 0.0164 | H12: =IFERROR(D12-SUM(E12:G12),"") -> 0.0772
A13: Trilobite: Agnostid | B13: 211874 | C13: Default pipeline (DecimatePro, 90%, UV+auto-error protection) | D13: 1.5322 | E13: 0.7279 | H13: =IFERROR(D13-SUM(E13:G13),"") -> 0.8043
A14: Blastoid: Pentremites godani (PRI 70771) | B14: 446670 | C14: Default pipeline (DecimatePro, 90%, UV+auto-error protection) | D14: 3.7456 | E14: 1.7293 | H14: =IFERROR(D14-SUM(E14:G14),"") -> 2.0163
A15: Vertebrate: T. rex tooth (PRI 55205) | B15: 108958 | C15: Default pipeline (DecimatePro, 90%, UV+auto-error protection) | D15: 0.918 | E15: 0.3642 | H15: =IFERROR(D15-SUM(E15:G15),"") -> 0.5538
A16: Loewe (lion) | B16: 405680 | C16: Default pipeline (DecimatePro, 90%, UV+auto-error protection) | D16: 4.5188 | E16: 1.1802 | H16: =IFERROR(D16-SUM(E16:G16),"") -> 3.3386
... A23: Realistic Heart (AI-generated) | B23: 31400 | C23: Default pipeline (DecimatePro, 90%, UV+auto-error protection) | D23: 1.0643 | E23: 0.1172 | H23: =IFERROR(D23-SUM(E23:G23),"") -> 0.9471
H24: =IFERROR(D24-SUM(E24:G24),"") -> 0
H25: =IFERROR(D25-SUM(E25:G25),"") -> 0
H26: =IFERROR(D26-SUM(E26:G26),"") -> 0
H27: =IFERROR(D27-SUM(E27:G27),"") -> 0
H28: =IFERROR(D28-SUM(E28:G28),"") -> 0
H29: =IFERROR(D29-SUM(E29:G29),"") -> 0
